Workbook

Sheet Configuration
B1: Instructions: Only Configure tabs and cells highlighted in Blue 1. Select number of BMS monitors in the daisy chain 2. Enter SPI clock period 3. Select ADC Mode 4. Enter SPI Transaction MCU overhead (%) 5. SPI Transaction MCU Overhead time constant
B2: Number of ICs | C2: 1
B4: SPI Clock Period | C4: 5e-07
B5: ADC Mode | C5: Continuous
B6: SPI Transaction MCU Overhead (%) | C6: 0.3 | D6: 40% is based on a 200MHz System Clock MCU test
B7: SPI Transaction MCU Overhead time constant | C7: 2e-05 | D7: 30us is based on a 200MHz System Clock MCU test

Sheet Loop Information
A1: Measurement & Diagnostic Summary
A2: Cycle # | B2: Cell Measurement | C2: SM_VCELL_RED | D2: SM_IIR_RED | E2: SM_SPI_RED | F2: SM_SPI_PEC | G2: SM_CLOCK_MON | H2: SM_FREEZE_SEQ | I2: SM_POWER_MON | J2: SM_POWER_OOR | K2: SM_CELL_OWD | L2: SM_VCELL_OOR | M2: SM_VGPIO_RED | N2: SM_VGPIO_OOR | O2: SM_SPI_CNT | P2: SM_TMOD_IND | Q2: SM_DIETEMP_OOR | R2: SM_SLEEP_IND | S2: SM_VREF2_OOR | T2: SM_NVM_ECC | U2: Comm Time Duration (Secs) | V2: Cycle PWM Disabled time (ms) | Y2: Created using ADBMS6830 Safety Manual Version 0.4 (PrD) | Z2: Rev 1.23
C3: SM1- | D3: SM2- | E3: SM3- | F3: SM4- | G3: SM5- | H3: SM6- | I3: SM7- | J3: SM8- | K3: SM9- | L3: SM12- | M3: SM14- | N3: SM15- | O3: SM16- | P3: SM17- | Q3: SM18- | R3: SM19- | S3: SM20- | T3: SM21- | Y3: Last edit | Z3: 44573
A4: 1 | B4: ✔ | C4: =IF(COUNTIF($Z$24:$Z$28,"*"&C3&"*"),"✔","") | D4: =IF(COUNTIF($Z$24:$Z$28,"*"&D3&"*"),"✔","") | E4: =IF(COUNTIF($Z$24:$Z$28,"*"&E3&"*"),"✔","") | F4: =IF(COUNTIF($Z$24:$Z$28,"*"&F3&"*"),"✔","") | G4: =IF(COUNTIF($Z$24:$Z$28,"*"&G3&"*"),"✔","") | H4: =IF(COUNTIF($Z$24:$Z$29,"*"&H3&"*"),"✔","") -> ✔ | I4: =IF(COUNTIF($Z$24:$Z$28,"*"&I3&"*"),"✔","") | J4: =IF(COUNTIF($Z$24:$Z$28,"*"&J3&"*"),"✔","") | K4: =IF(COUNTIF($Z$24:$Z$28,"*"&K3&"*"),"✔","") | L4: =IF(COUNTIF($Z$24:$Z$28,"*"&L3&"*"),"✔","") -> ✔ | M4: =IF(COUNTIF($Z$24:$Z$28,"*"&M3&"*"),"✔","") | N4: =IF(COUNTIF($Z$24:$Z$28,"*"&N3&"*"),"✔","") | O4: =IF(COUNTIF($Z$24:$Z$28,"*"&O3&"*"),"✔","") | P4: =IF(COUNTIF($Z$24:$Z$28,"*"&P3&"*"),"✔","") | ... T4: =IF(COUNTIF($Z$24:$Z$28,"*"&T3&"*"),"✔","") | U4: =AA31+0.0022 -> 0.0030632 | V4: =AE32 -> 0
A5: 2 | B5: ✔ | C5: =IF(COUNTIF($Z$35:$Z$37,"*"&C3&"*"),"✔","") | D5: =IF(COUNTIF($Z$35:$Z$37,"*"&D3&"*"),"✔","") | E5: =IF(COUNTIF($Z$35:$Z$37,"*"&E3&"*"),"✔","") | F5: =IF(COUNTIF($Z$35:$Z$37,"*"&F3&"*"),"✔","") | G5: =IF(COUNTIF($Z$35:$Z$37,"*"&G3&"*"),"✔","") | H5: =IF(COUNTIF($Z$35:$Z$37,"*"&H3&"*"),"✔","") | I5: =IF(COUNTIF($Z$35:$Z$37,"*"&I3&"*"),"✔","") | J5: =IF(COUNTIF($Z$35:$Z$37,"*"&J3&"*"),"✔","") | ... T5: =IF(COUNTIF($Z$35:$Z$37,"*"&T3&"*"),"✔","") | U5: =AA39 -> 0.0007392 | V5: =AE40 -> 0.0092608
A6: 3 | B6: ✔ | C6: =IF(COUNTIF($Z$43:$Z$44,"*"&C3&"*"),"✔","") | D6: =IF(COUNTIF($Z$43:$Z$44,"*"&D3&"*"),"✔","") | E6: =IF(COUNTIF($Z$43:$Z$44,"*"&E3&"*"),"✔","") | F6: =IF(COUNTIF($Z$43:$Z$44,"*"&F3&"*"),"✔","") | G6: =IF(COUNTIF($Z$43:$Z$44,"*"&G3&"*"),"✔","") | H6: =IF(COUNTIF($Z$43:$Z$44,"*"&H3&"*"),"✔","") | I6: =IF(COUNTIF($Z$43:$Z$44,"*"&I3&"*"),"✔","") | J6: =IF(COUNTIF($Z$43:$Z$44,"*"&J3&"*"),"✔","") | ... T6: =IF(COUNTIF($Z$43:$Z$44,"*"&T3&"*"),"✔","") | U6: =AA45 -> 0.000576 | V6: =AE46 -> 0.01
A7: 4 | B7: ✔ | C7: =IF(COUNTIF($Z$49:$Z$50,"*"&C3&"*"),"✔","") | D7: =IF(COUNTIF($Z$49:$Z$50,"*"&D3&"*"),"✔","") | E7: =IF(COUNTIF($Z$49:$Z$50,"*"&E3&"*"),"✔","") | F7: =IF(COUNTIF($Z$49:$Z$50,"*"&F3&"*"),"✔","") | G7: =IF(COUNTIF($Z$49:$Z$50,"*"&G3&"*"),"✔","") | H7: =IF(COUNTIF($Z$49:$Z$50,"*"&H3&"*"),"✔","") | I7: =IF(COUNTIF($Z$49:$Z$50,"*"&I3&"*"),"✔","") | J7: =IF(COUNTIF($Z$49:$Z$50,"*"&J3&"*"),"✔","") | ... T7: =IF(COUNTIF($Z$49:$Z$50,"*"&T3&"*"),"✔","") | U7: =AA52+0.0024 -> 0.0036336 | V7: =AE53 -> 0.000576
A8: 5 | B8: ✔ | C8: =IF(COUNTIF($Z$56:$Z$57,"*"&C3&"*"),"✔","") | D8: =IF(COUNTIF($Z$56:$Z$57,"*"&D3&"*"),"✔","") | E8: =IF(COUNTIF($Z$56:$Z$57,"*"&E3&"*"),"✔","") | F8: =IF(COUNTIF($Z$56:$Z$57,"*"&F3&"*"),"✔","") | G8: =IF(COUNTIF($Z$56:$Z$57,"*"&G3&"*"),"✔","") | H8: =IF(COUNTIF($Z$56:$Z$57,"*"&H3&"*"),"✔","") | I8: =IF(COUNTIF($Z$56:$Z$57,"*"&I3&"*"),"✔","") | J8: =IF(COUNTIF($Z$56:$Z$57,"*"&J3&"*"),"✔","") | ... T8: =IF(COUNTIF($Z$56:$Z$57,"*"&T3&"*"),"✔","") | U8: =AA58 -> 0.000576 | V8: =AE59 -> 0
A9: 6 | B9: ✔ | C9: =IF(COUNTIF($Z$62:$Z$63,"*"&C3&"*"),"✔","") | D9: =IF(COUNTIF($Z$62:$Z$63,"*"&D3&"*"),"✔","") | E9: =IF(COUNTIF($Z$62:$Z$63,"*"&E3&"*"),"✔","") | F9: =IF(COUNTIF($Z$62:$Z$63,"*"&F3&"*"),"✔","") | G9: =IF(COUNTIF($Z$62:$Z$63,"*"&G3&"*"),"✔","") | H9: =IF(COUNTIF($Z$62:$Z$63,"*"&H3&"*"),"✔","") | I9: =IF(COUNTIF($Z$62:$Z$63,"*"&I3&"*"),"✔","") | J9: =IF(COUNTIF($Z$62:$Z$63,"*"&J3&"*"),"✔","") | ... T9: =IF(COUNTIF($Z$62:$Z$63,"*"&T3&"*"),"✔","") | U9: =AA64 -> 0.001152 | V9: =AE65 -> 0.0088408 | Y9: FDTI | Z9: =J18 -> 0.1 | AA9: Configures the Target FDTI
A10: 7 | B10: ✔ | C10: =IF(COUNTIF($Z$68:$Z$69,"*"&C3&"*"),"✔","") | D10: =IF(COUNTIF($Z$68:$Z$69,"*"&D3&"*"),"✔","") | E10: =IF(COUNTIF($Z$68:$Z$69,"*"&E3&"*"),"✔","") | F10: =IF(COUNTIF($Z$68:$Z$69,"*"&F3&"*"),"✔","") | G10: =IF(COUNTIF($Z$68:$Z$69,"*"&G3&"*"),"✔","") | H10: =IF(COUNTIF($Z$68:$Z$69,"*"&H3&"*"),"✔","") | I10: =IF(COUNTIF($Z$68:$Z$69,"*"&I3&"*"),"✔","") | J10: =IF(COUNTIF($Z$68:$Z$69,"*"&J3&"*"),"✔","") | ... T10: =IF(COUNTIF($Z$68:$Z$69,"*"&T3&"*"),"✔","") | U10: =AA70 -> 0.000576 | V10: =AE71 -> 0 | Y10: Measurement & Diagnostic Total Time
A11: 8 | B11: ✔ | C11: =IF(COUNTIF($Z$74:$Z$75,"*"&C3&"*"),"✔","") | D11: =IF(COUNTIF($Z$74:$Z$75,"*"&D3&"*"),"✔","") | E11: =IF(COUNTIF($Z$74:$Z$75,"*"&E3&"*"),"✔","") | F11: =IF(COUNTIF($Z$74:$Z$75,"*"&F3&"*"),"✔","") | G11: =IF(COUNTIF($Z$74:$Z$75,"*"&G3&"*"),"✔","") | H11: =IF(COUNTIF($Z$74:$Z$75,"*"&H3&"*"),"✔","") | I11: =IF(COUNTIF($Z$74:$Z$75,"*"&I3&"*"),"✔","") | J11: =IF(COUNTIF($Z$74:$Z$75,"*"&J3&"*"),"✔","") | ... T11: =IF(COUNTIF($Z$74:$Z$75,"*"&T3&"*"),"✔","") | U11: =AA76 -> 0.0010704 | V11: =AE77 -> 0 | Y11: Cell Data Update Rate | Z11: =J20 -> 0.01 | AA11: Configures Cell data update interval. Time calculations are based on this target interval
A12: 9 | B12: ✔ | C12: =IF(COUNTIF($Z$80:$Z$81,"*"&C3&"*"),"✔","") | D12: =IF(COUNTIF($Z$80:$Z$81,"*"&D3&"*"),"✔","") | E12: =IF(COUNTIF($Z$80:$Z$81,"*"&E3&"*"),"✔","") | F12: =IF(COUNTIF($Z$80:$Z$81,"*"&F3&"*"),"✔","") | G12: =IF(COUNTIF($Z$80:$Z$81,"*"&G3&"*"),"✔","") | H12: =IF(COUNTIF($Z$80:$Z$81,"*"&H3&"*"),"✔","") | I12: =IF(COUNTIF($Z$80:$Z$81,"*"&I3&"*"),"✔","") | J12: =IF(COUNTIF($Z$80:$Z$81,"*"&J3&"*"),"✔","") | ... T12: =IF(COUNTIF($Z$80:$Z$81,"*"&T3&"*"),"✔","") | U12: =AA82 -> 0.0012352 | V12: =AE83 -> 0
A13: 10 | B13: ✔ | C13: =IF(COUNTIF($Z$85:$Z$87,"*"&C3&"*"),"✔","") -> ✔ | D13: =IF(COUNTIF($Z$85:$Z$87,"*"&D3&"*"),"✔","") -> ✔ | E13: =IF(COUNTIF($Z$85:$Z$87,"*"&E3&"*"),"✔","") -> ✔ | F13: =IF(COUNTIF($Z$85:$Z$87,"*"&F3&"*"),"✔","") -> ✔ | G13: =IF(COUNTIF($Z$85:$Z$87,"*"&G3&"*"),"✔","") -> ✔ | H13: =IF(COUNTIF($Z$85:$Z$87,"*"&H3&"*"),"✔","") | I13: =IF(COUNTIF($Z$85:$Z$87,"*"&I3&"*"),"✔","") -> ✔ | J13: =IF(COUNTIF($Z$85:$Z$87,"*"&J3&"*"),"✔","") -> ✔ | ... T13: =IF(COUNTIF($Z$85:$Z$87,"*"&T3&"*"),"✔","") -> ✔ | U13: =AA90 -> 0.0012344 | V13: =AE90 -> 0
A14: SM Summary | B14: =IF(COUNTIF(B4:B13,"✔"),"✔","") -> ✔ | C14: =IF(COUNTIF(C4:C13,"✔"),"✔","") -> ✔ | D14: =IF(COUNTIF(D4:D13,"✔"),"✔","") -> ✔ | E14: =IF(COUNTIF(E4:E13,"✔"),"✔","") -> ✔ | F14: =IF(COUNTIF(F4:F13,"✔"),"✔","") -> ✔ | G14: =IF(COUNTIF(G4:G13,"✔"),"✔","") -> ✔ | H14: =IF(COUNTIF(H4:H13,"✔"),"✔","") -> ✔ | I14: =IF(COUNTIF(I4:I13,"✔"),"✔","") -> ✔ | ... T14: =IF(COUNTIF(T4:T13,"✔"),"✔","") -> ✔
V15: Total Available PWM discharge time Per FDTI | W15: =Z9-SUM(V4:V13) -> 0.0713224
V16: PWM MAX Duty Cycle | W16: =AE95 -> 0.713224
A18: FDTI | J18: 0.1 | U18: Configures the Target FDTI
A19: Measurement & Diagnostic Total Time | J19: =AA94 -> 0.013856 | Y19: Note that delays are assumed to be implemented as non-blocking. SPI communication time includes SPI transaction time + MCU overhead time
A20: Cell Data Update Rate | J20: 0.01 | U20: Configures Cell data update interval. Time calculations are based on this target interval
X23: No. | Y23: Meas/Diagn Functions | Z23: SMs Covered | AA23: Execution Time(s) | AB23: Avg Func Current(A) | AC23: Coulomb(A*s) | AE23: PWM Disabled time
Y24: Cycle 1 | AG24: START | AH24: END | AI24: Time
X25: 1 | Y25: ='Safety Mechanism Timing'!B187 -> Cell Measurements - Cycle 1 | Z25: ='Safety Mechanism Timing'!B197 -> SM12- | AA25: ='Safety Mechanism Timing'!G197 -> 0.000576 | AB25: ='Safety Mechanism Timing'!H197 -> 0.00825 | AC25: =AB25*AA25 -> 4.752e-06 | AE25: ='Safety Mechanism Timing'!J197 -> 0 | AG25: =(X25-1)*$J$20 -> 0 | AH25: =AG25+AA25 -> 0.000576 | AI25: =AH25-AG25 -> 0.000576 | AK25: =_xlfn.CONCAT("Periodic Cell Measurement-",Z25) -> Periodic Cell Measurement-SM12-
X26: 1.1 | Y26: ='Safety Mechanism Timing'!B199 -> SM6 - Initialization | Z26: ='Safety Mechanism Timing'!B203 | AA26: ='Safety Mechanism Timing'!G203 -> 8.16e-05 | AB26: ='Safety Mechanism Timing'!H203 -> 0.00825 | AC26: =AB26*AA26 -> 6.732e-07 | AE26: ='Safety Mechanism Timing'!J203 -> 0 | AG26: =AH25 -> 0.000576 | AH26: =AG26+AA26 -> 0.0006576 | AI26: =AH26-AG26 -> 8.16e-05 | AK26: =_xlfn.CONCAT(Y26,"-",Z26) -> SM6 - Initialization-
X27: 1.2 | Y27: ='Safety Mechanism Timing'!B205 -> SM6 - 2.2ms Delay | Z27: ='Safety Mechanism Timing'!B208 | AB27: ='Safety Mechanism Timing'!H208 -> 0 | AC27: =AB27*AA27 -> 0 | AE27: ='Safety Mechanism Timing'!J208 -> 0 | AG27: =AH26 -> 0.0006576 | AH27: =AG27+AA27+0.0022 -> 0.0028576 | AI27: =AH27-AG27 -> 0.0022 | AK27: =_xlfn.CONCAT(Y27,"-",Z27) -> SM6 - 2.2ms Delay-
X28: 1.3 | Y28: ='Safety Mechanism Timing'!B210 -> SM6 - Cell Value Out-of-Range Test | Z28: ='Safety Mechanism Timing'!B214 | AA28: ='Safety Mechanism Timing'!G214 -> 0.0001232 | AB28: ='Safety Mechanism Timing'!H214 -> 0.00825 | AC28: =AB28*AA28 -> 1.0164e-06 | AE28: ='Safety Mechanism Timing'!J214 -> 0 | AG28: =AH27 -> 0.0028576 | AH28: =AG28+AA28 -> 0.0029808 | AI28: =AH28-AG28 -> 0.0001232 | AK28: =_xlfn.CONCAT(Y28,"-",Z28) -> SM6 - Cell Value Out-of-Range Test-
X29: 1.4 | Y29: ='Safety Mechanism Timing'!B216 -> SM6 - Cell Value In-Range test | Z29: ='Safety Mechanism Timing'!B219 -> SM6- | AA29: ='Safety Mechanism Timing'!G219 -> 8.24e-05 | AE29: ='Safety Mechanism Timing'!J219 -> 0
AE30: ='Safety Mechanism Timing'!J224 -> 0
Z31: SPI comm time | AA31: =SUM(AA25:AA29) -> 0.0008632
Z32: Cycle Time Margin | AA32: =IF((($Z$11-AA31)-0.0022) >0,($Z$11-AA31)-0.0022,0) -> 0.0069368 | AD32: Cycle PWM Disabled Time | AE32: =SUM(AE25:AE29) -> 0
Y34: Cycle 2 | AG34: START | AH34: END | AI34: Time
X35: 2 | Y35: ='Safety Mechanism Timing'!B226 -> Cell Measurements - Cycle 2 | Z35: ='Safety Mechanism Timing'!B236 -> SM12- | AA35: ='Safety Mechanism Timing'!G236 -> 0.000576 | AB35: ='Safety Mechanism Timing'!H236 -> 0.00825 | AC35: =AB35*AA35 -> 4.752e-06 | AE35: ='Safety Mechanism Timing'!J236 -> 0 | AG35: =(X35-1)*$J$20 -> 0.01 | AH35: =AG35+AA35 -> 0.010576 | AI35: =AH35-AG35 -> 0.000576 | AK35: =_xlfn.CONCAT("Periodic Cell Measurement-",Z35) -> Periodic Cell Measurement-SM12-
X36: 2.1 | Y36: ='Safety Mechanism Timing'!B238 -> Trigger AUX ADC & Redundant AUX ADC | Z36: ='Safety Mechanism Timing'!B248 | AA36: ='Safety Mechanism Timing'!G243 -> 0.0001224 | AB36: ='Safety Mechanism Timing'!H243 -> 0.010256667 | AC36: =AB36*AA36 -> 1.255416e-06 | AE36: ='Safety Mechanism Timing'!J243 -> 0 | AG36: =AH35 -> 0.010576 | AH36: =AG36+AA36 -> 0.0106984 | AI36: =AH36-AG36 -> 0.0001224 | AK36: =_xlfn.CONCAT(Y36,"-",Z36) -> Trigger AUX ADC & Redundant AUX ADC-
X37: 2.2 | Y37: ='Safety Mechanism Timing'!B245 -> SM1 - Trigger Cell Redundant Measuments | Z37: ='Safety Mechanism Timing'!B248 | AA37: ='Safety Mechanism Timing'!G248 -> 4.08e-05 | AB37: ='Safety Mechanism Timing'!H248 -> 0.01126 | AC37: =AB37*AA37 -> 4.59408e-07 | AE37: ='Safety Mechanism Timing'!J248 -> 0 | AG37: =AH36 -> 0.0106984 | AH37: =AG37+AA37 -> 0.0107392 | AI37: =AH37-AG37 -> 4.08e-05 | AK37: =_xlfn.CONCAT(Y37,"-",Z37) -> SM1 - Trigger Cell Redundant Measuments-
Y38: 1st Delay (~3.0ms) | AE38: ='Safety Mechanism Timing'!J253 -> 0.0092608
Z39: SPI comm time | AA39: =SUM(AA35:AA38) -> 0.0007392
Z40: Cycle Time Margin | AA40: =IF(($Z$11-AA39) > 0, $Z$11-AA39,0) -> 0.0092608 | AD40: Cycle PWM Disabled Time | AE40: =SUM(AE35:AE38) -> 0.0092608
Y42: Cycle 3 | AG42: START | AH42: END | AI42: Time
X43: 3 | Y43: ='Safety Mechanism Timing'!B255 -> Cell Measurements - Cycle 3 | Z43: ='Safety Mechanism Timing'!B265 -> SM12- | AA43: ='Safety Mechanism Timing'!G265 -> 0.000576 | AB43: ='Safety Mechanism Timing'!H265 -> 0.00825 | AC43: =AB43*AA43 -> 4.752e-06 | AE43: ='Safety Mechanism Timing'!J265 -> 0.000576 | AG43: =(X43-1)*$J$20 -> 0.02 | AH43: =AG43+AA43 -> 0.020576 | AI43: =AH43-AG43 -> 0.000576 | AK43: =_xlfn.CONCAT("Periodic Cell Measurement-",Z43) -> Periodic Cell Measurement-SM12-
Y44: 2nd Delay (~ 3.8 ms) | AE44: ='Safety Mechanism Timing'!J270 -> 0.009424
Z45: SPI comm time | AA45: =SUM(AA43) -> 0.000576
...

Sheet Safety Mechanism Timing
B1: Cell Data Update Rate | C1: ='Loop Information'!Z11 -> 0.01 | I1: Comments
B2: SPF SM Main Functions | C2: Main SMs Covered | D2: All SMs Covered | E2: Brief Description | F2: Execution Time(s) | G2: Average Current(A) | H2: PWM Disabled Time(s)
B3: =B22 -> Initialization | C3: N/A | D3: =B30 | E3: C-ADC Continuous Mode Initializtion | F3: =G30 -> 0.0004112 | G3: =H30 -> 0.0078600584 | H3: =J30 -> 0 | I3: Not included in Normal Operation
B4: =B32 -> Cell Measurement Normal Operation | C4: N/A | D4: =B43 -> SM12- | E4: Normal AVG or FILT Cell Measurement | F4: =G43 -> 0.000576 | G4: =H43 -> 0.00825 | H4: =J43 -> 0
B5: =B45 -> Cell Measurements with SM6 | C5: SM6- | D5: =B62 -> SM6-SM12- | E5: Detect the no clocks and wrong freeze protocol state with AVG or FILT Cell Measurement | F5: =G62 -> 0.01 | G5: =H62 -> 0.00071214 | H5: =J62 -> 0
B6: =B64 -> Cell Measurement with SM1 & SM9 | C6: SM1-SM9- | D6: =B147 -> SM12-SM9- | E6: Redundant Cell Measurement and Open Wire Detection with AVG or FILT Cell Measurements | F6: =G147 -> 0.0604128 | G6: =H147 -> 0.00072517122 | H6: =J147 -> 0.0375592
B7: =B149 -> Cell Measurement with AUX-ADC | C7: SM8-SM14-SM15-SM18-SM20- | D7: =B185 -> SM12-SM15-SM8-SM12-SM18-SM20-SM14- | E7: Read AUX-ADC Results with AVG or FILT Cell Measurement | F7: =G185 -> 0.020164 | G7: =H185 -> 0.00097187145 | H7: =J185 -> 0
B8: Total | F8: =SUM(F4:F7) -> 0.0911528 | H8: =SUM(H4:H7) -> 0.0375592
B10: Latent Fault SM Functions | C10: Main SMs Covered | D10: Additional SMs Covered | E10: Brief Description | F10: Execution Time(s) | G10: Average Current(A) | H10: PWM Discharge Time(s)
B11: =B445 -> SM_ SPI_PEC_DIAG | C11: SM22- | D11: =B481 -> SM22- | F11: =G481 -> 0.0020528 | G11: =H481 -> 0.0093268433 | H11: =J481 -> 0
B12: =B483 -> SM_POWER_MON_DIAG | C12: SM23- | D12: =B497 -> SM23- | F12: =G497 -> 0.0047408 | G12: =H497 -> 0.0013409585 | H12: =J497 -> 0
B13: =B499 -> SM_CLOCK_MON_DIAG | C13: SM24- | D13: =B514 -> SM24- | F13: =G514 -> 0.0048232 | G13: =H514 -> 0.0014589932 | H13: =J514 -> 0
B14: =B516 -> SM_SPI_RED_DIAG | C14: SM25- | D14: =B522 -> SM25- | F14: =G522 -> 0.0003296 | G14: =H522 -> 0.00825 | H14: =J522 -> 0
B15: =B524 -> SM_TMOD_IND_DIAG | C15: SM26- | D15: =B532 -> SM26- | F15: =G532 -> 0.0004944 | G15: =H532 -> 0.00825 | H15: =J532 -> 0
B16: =B534 -> SM_THSD_IND_DIAG | C16: SM27- | D16: =B542 -> SM27- | F16: =G542 -> 0.0004944 | G16: =H542 -> 0.00825 | H16: =J542 -> 0
B17: =B544 -> SM_VCELL_CMP_DIAG | C17: SM28- | D17: =B552 -> SM28- | F17: =G552 -> 0.0042464 | G17: =H552 -> 0.00053655237 | H17: =J552 -> 0
B18: =B554 -> SM_CELL_OWD_DIAG | C18: SM29- | D18: =B557 -> SM29- | F18: =G557 -> 0 | G18: =H557 -> 0 | H18: =J557 -> 0
B19: =B559 -> SM_AUXREGS_DIAG | C19: SM30- | D19: =B569 -> SM30- | F19: =G569 -> 0.020452 | G19: =H569 -> 0.00018833405 | H19: =J569 -> 0
B20: =B571 -> SM_NVM_ECC_DIAG | C20: SM31- | D20: =B579 -> SM31- | F20: =G579 -> 0.0004944 | G20: =H579 -> 0.00825 | H20: =J579 -> 0
B22: Initialization
B23: Special Notification | C23: Command | D23: CMDs | E23: Safety Mechanism | F23: Current(A) | G23: Timing(s) | H23: Coulomb(A*s) | J23: PWM Disabled time
C24: SRST | F24: =VLOOKUP(C24,'CMD Timing and Current'!$A$2:$I$96,9,FALSE) -> 0.00131 | G24: =VLOOKUP(C24,'CMD Timing and Current'!$A$2:$I$96,6,FALSE) -> 4.08e-05 | H24: =F24*G24 -> 5.3448e-08 | I24: Initialization with default configurations | J24: 0
C25: WRCFGA | F25: =VLOOKUP(C25,'CMD Timing and Current'!$A$2:$I$96,9,FALSE) -> 0.00825 | G25: =VLOOKUP(C25,'CMD Timing and Current'!$A$2:$I$96,6,FALSE) -> 8.24e-05 | H25: =F25*G25 -> 6.798e-07 | I25: Initialization with default configurations and Corner Frequency FC[2:0] | J25: 0
C26: RDCFGA | F26: =VLOOKUP(C26,'CMD Timing and Current'!$A$2:$I$96,9,FALSE) -> 0.00825 | G26: =VLOOKUP(C26,'CMD Timing and Current'!$A$2:$I$96,6,FALSE) -> 8.24e-05 | H26: =F26*G26 -> 6.798e-07 | I26: Read the Configuration register group A data | J26: 0
C27: CLRFLAG | F27: =VLOOKUP(C27,'CMD Timing and Current'!$A$2:$I$96,9,FALSE) -> 0.00825 | G27: =VLOOKUP(C27,'CMD Timing and Current'!$A$2:$I$96,6,FALSE) -> 8.24e-05 | H27: =F27*G27 -> 6.798e-07 | I27: If any flags that can be cleared by CLRFLG command are set, send CLRFLG command | J27: 0
C28: RDSTATC | F28: =VLOOKUP(C28,'CMD Timing and Current'!$A$2:$I$96,9,FALSE) -> 0.00825 | G28: =VLOOKUP(C28,'CMD Timing and Current'!$A$2:$I$96,6,FALSE) -> 8.24e-05 | H28: =F28*G28 -> 6.798e-07 | I28: make sure the CSxFLT, SPIFLT,OSCCHK,VA_OV, VA_UV, VD_OV,VD_UV,TMODECHK,THSD,SLEEP are zero. | J28: 0
B29: Trigger C-ADC in Continuous mode | C29: ADCV | F29: =VLOOKUP(C29,'CMD Timing and Current'!$A$2:$I$96,9,FALSE) -> 0.01126 | G29: =VLOOKUP(C29,'CMD Timing and Current'!$A$2:$I$96,6,FALSE) -> 4.08e-05 | H29: =F29*G29 -> 4.59408e-07 | I29: Trigger C-ADCs in continuous mode with ADCV command DCP = 0 CONT = 1 OW = 00 RD = 0 | J29: 0
B30: =_xlfn.CONCAT(E24:E29) | E30: Total Time & Average Current | G30: =SUM(G24:G29) -> 0.0004112 | H30: =SUM(H24:H29)/G30 -> 0.0078600584 | J30: =SUM(J24:J29) -> 0
B32: Cell Measurement Normal Operation | D32: Assume ADCV is already in continuous mode
B33: Special Notification | C33: Command | D33: CMDs | E33: Safety Mechanism | F33: Current(A) | G33: Timing(s) | H33: Coulomb(A*s) | J33: PWM Disabled time
C34: SNAP | F34: =VLOOKUP(C34,'CMD Timing and Current'!$A$2:$I$96,9,FALSE) -> 0.00825 | G34: =VLOOKUP(C34,'CMD Timing and Current'!$A$2:$I$96,6,FALSE) -> 4.08e-05 | H34: =F34*G34 -> 3.366e-07 | I34: Send SNAP command | J34: 0
I35: Read Conversion Counter to check if the data is refreshed and CSxFLT, SPIFLT,OSCCHK,VA_OV, VA_UV, VD_OV,VD_UV,TMODECHK,THSD,SLEEP, CED, CMED, SED, SMED are zero. | J35: 0
B36: RD DATA1 | C36: RDFCA | E36: SM12- | F36: =VLOOKUP(C36,'CMD Timing and Current'!$A$2:$I$96,9,FALSE) -> 0.00825 | G36: =VLOOKUP(C36,'CMD Timing and Current'!$A$2:$I$96,6,FALSE) -> 8.24e-05 | H36: =F36*G36 -> 6.798e-07 | I36: Verify Filtered Cell Voltage Register Group A to F are within the range | J36: 0
B37: RD DATA1 | C37: RDFCB | F37: =VLOOKUP(C37,'CMD Timing and Current'!$A$2:$I$96,9,FALSE) -> 0.00825 | G37: =VLOOKUP(C37,'CMD Timing and Current'!$A$2:$I$96,6,FALSE) -> 8.24e-05 | H37: =F37*G37 -> 6.798e-07 | I37: Verify Filtered Cell Voltage Register Group A to F are within the range | J37: 0
B38: RD DATA1 | C38: RDFCC | F38: =VLOOKUP(C38,'CMD Timing and Current'!$A$2:$I$96,9,FALSE) -> 0.00825 | G38: =VLOOKUP(C38,'CMD Timing and Current'!$A$2:$I$96,6,FALSE) -> 8.24e-05 | H38: =F38*G38 -> 6.798e-07 | I38: Verify Filtered Cell Voltage Register Group A to F are within the range | J38: 0
B39: RD DATA1 | C39: RDFCD | F39: =VLOOKUP(C39,'CMD Timing and Current'!$A$2:$I$96,9,FALSE) -> 0.00825 | G39: =VLOOKUP(C39,'CMD Timing and Current'!$A$2:$I$96,6,FALSE) -> 8.24e-05 | H39: =F39*G39 -> 6.798e-07 | I39: Verify Filtered Cell Voltage Register Group A to F are within the range | J39: 0
B40: RD DATA1 | C40: RDFCE | F40: =VLOOKUP(C40,'CMD Timing and Current'!$A$2:$I$96,9,FALSE) -> 0.00825 | G40: =VLOOKUP(C40,'CMD Timing and Current'!$A$2:$I$96,6,FALSE) -> 8.24e-05 | H40: =F40*G40 -> 6.798e-07 | I40: Verify Filtered Cell Voltage Register Group A to F are within the range | J40: 0
B41: RD DATA1 | C41: RDFCF | F41: =VLOOKUP(C41,'CMD Timing and Current'!$A$2:$I$96,9,FALSE) -> 0.00825 | G41: =VLOOKUP(C41,'CMD Timing and Current'!$A$2:$I$96,6,FALSE) -> 8.24e-05 | H41: =F41*G41 -> 6.798e-07 | I41: Verify Filtered Cell Voltage Register Group A to F are within the range | J41: 0
C42: UNSNAP | F42: =VLOOKUP(C42,'CMD Timing and Current'!$A$2:$I$96,9,FALSE) -> 0.00825 | G42: =VLOOKUP(C42,'CMD Timing and Current'!$A$2:$I$96,6,FALSE) -> 4.08e-05 | H42: =F42*G42 -> 3.366e-07 | I42: Send UNSNAP command | J42: 0
B43: =_xlfn.CONCAT(E34:E42) -> SM12- | E43: Total Time & Average Current | G43: =SUM(G34:G42) -> 0.000576 | H43: =SUM(H34:H42)/G43 -> 0.00825 | J43: =SUM(J34:J42) -> 0
...

Sheet LatentFaults
E1: =B7 -> SM_ SPI_PEC_DIAG | F1: =B8 -> SM_POWER_MON_DIAG | G1: =B9 -> SM_CLOCK_MON_DIAG | H1: =B10 -> SM_SPI_RED_DIAG | I1: =B11 -> SM_TMOD_IND_DIAG | J1: =B12 -> SM_THSD_IND_DIAG | K1: =B13 -> SM_VCELL_CMP_DIAG | L1: =B14 -> SM_CELL_OWD_DIAG | M1: =B15 -> SM_AUXREGS_DIAG | N1: =B16 -> SM_NVM_ECC_DIAG
E2: SM22- | F2: SM23- | G2: SM24- | H2: SM25- | I2: SM26- | J2: SM27- | K2: SM28- | L2: SM29- | M2: SM30- | N2: SM31-
B7: ='Safety Mechanism Timing'!B11 -> SM_ SPI_PEC_DIAG | C7: ='Safety Mechanism Timing'!D11 -> SM22- | D7: ='Safety Mechanism Timing'!F11 -> 0.0020528
B8: ='Safety Mechanism Timing'!B12 -> SM_POWER_MON_DIAG | C8: ='Safety Mechanism Timing'!D12 -> SM23- | D8: ='Safety Mechanism Timing'!F12 -> 0.0047408
B9: ='Safety Mechanism Timing'!B13 -> SM_CLOCK_MON_DIAG | C9: ='Safety Mechanism Timing'!D13 -> SM24- | D9: ='Safety Mechanism Timing'!F13 -> 0.0048232
B10: ='Safety Mechanism Timing'!B14 -> SM_SPI_RED_DIAG | C10: ='Safety Mechanism Timing'!D14 -> SM25- | D10: ='Safety Mechanism Timing'!F14 -> 0.0003296
B11: ='Safety Mechanism Timing'!B15 -> SM_TMOD_IND_DIAG | C11: ='Safety Mechanism Timing'!D15 -> SM26- | D11: ='Safety Mechanism Timing'!F15 -> 0.0004944
B12: ='Safety Mechanism Timing'!B16 -> SM_THSD_IND_DIAG | C12: ='Safety Mechanism Timing'!D16 -> SM27- | D12: ='Safety Mechanism Timing'!F16 -> 0.0004944
B13: ='Safety Mechanism Timing'!B17 -> SM_VCELL_CMP_DIAG | C13: ='Safety Mechanism Timing'!D17 -> SM28- | D13: ='Safety Mechanism Timing'!F17 -> 0.0042464
B14: ='Safety Mechanism Timing'!B18 -> SM_CELL_OWD_DIAG | C14: ='Safety Mechanism Timing'!D18 -> SM29- | D14: ='Safety Mechanism Timing'!F18 -> 0
B15: ='Safety Mechanism Timing'!B19 -> SM_AUXREGS_DIAG | C15: ='Safety Mechanism Timing'!D19 -> SM30- | D15: ='Safety Mechanism Timing'!F19 -> 0.020452
B16: ='Safety Mechanism Timing'!B20 -> SM_NVM_ECC_DIAG | C16: ='Safety Mechanism Timing'!D20 -> SM31- | D16: ='Safety Mechanism Timing'!F20 -> 0.0004944
C17: execution time | D17: =SUM(D7:D16) -> 0.038128

Sheet CMD Timing and Current
A1: CMD | B1: CMD(bytes) | C1: data (bytes) | D1: data time(s) | E1: execution time(s) | F1: Total Time(s) | G1: Core State | H1: isoState | I1: Current | K1: Total Bytes | L1: Description | P1: OverheadPercentage Adjust (Data transmitted) | Q1: =1+(Configuration!C6) -> 1.3
A2: WRCFGA | B2: 4 | C2: =8*Configuration!$C$2 -> 8 | D2: =((B2*8*Configuration!$C$4)+(C2*8*Configuration!$C$4))*$Q$1 -> 6.24e-05 | E2: 0 | F2: =(D2+E2+$Q$3) -> 8.24e-05 | G2: Refon | H2: Isoact | I2: =VLOOKUP(G2,$M$19:$N$23,2,FALSE) + VLOOKUP(H2,$M$19:$N$24,2,FALSE) -> 0.00825 | K2: =SUM(B2:C2) -> 12 | L2: Write Configuration Register Group A
A3: WRCFGB | B3: 4 | C3: =8*Configuration!$C$2 -> 8 | D3: =((B3*8*Configuration!$C$4)+(C3*8*Configuration!$C$4))*$Q$1 -> 6.24e-05 | E3: 0 | F3: =(D3+E3+$Q$3) -> 8.24e-05 | G3: Refon | H3: Isoact | I3: =VLOOKUP(G3,$M$19:$N$23,2,FALSE) + VLOOKUP(H3,$M$19:$N$24,2,FALSE) -> 0.00825 | K3: =SUM(B3:C3) -> 12 | L3: Write Configuration Register Group B | P3: SPI Transaction Overhead time constant | Q3: =Configuration!C7 -> 2e-05
A4: RDCFGA | B4: 4 | C4: =8*Configuration!$C$2 -> 8 | D4: =((B4*8*Configuration!$C$4)+(C4*8*Configuration!$C$4))*$Q$1 -> 6.24e-05 | E4: 0 | F4: =(D4+E4+$Q$3) -> 8.24e-05 | G4: Refon | H4: Isoact | I4: =VLOOKUP(G4,$M$19:$N$23,2,FALSE) + VLOOKUP(H4,$M$19:$N$24,2,FALSE) -> 0.00825 | K4: =SUM(B4:C4) -> 12 | L4: Read Configuration Register Group A
A5: RDCFGB | B5: 4 | C5: =8*Configuration!$C$2 -> 8 | D5: =((B5*8*Configuration!$C$4)+(C5*8*Configuration!$C$4))*$Q$1 -> 6.24e-05 | E5: 0 | F5: =(D5+E5+$Q$3) -> 8.24e-05 | G5: Refon | H5: Isoact | I5: =VLOOKUP(G5,$M$19:$N$23,2,FALSE) + VLOOKUP(H5,$M$19:$N$24,2,FALSE) -> 0.00825 | K5: =SUM(B5:C5) -> 12 | L5: Read Configuration Register Group B
A6: RDCVA | B6: 4 | C6: =8*Configuration!$C$2 -> 8 | D6: =((B6*8*Configuration!$C$4)+(C6*8*Configuration!$C$4))*$Q$1 -> 6.24e-05 | E6: 0 | F6: =(D6+E6+$Q$3) -> 8.24e-05 | G6: Refon | H6: Isoact | I6: =VLOOKUP(G6,$M$19:$N$23,2,FALSE) + VLOOKUP(H6,$M$19:$N$24,2,FALSE) -> 0.00825 | K6: =SUM(B6:C6) -> 12 | L6: Read Cell Voltage Register Group A
A7: RDCVB | B7: 4 | C7: =8*Configuration!$C$2 -> 8 | D7: =((B7*8*Configuration!$C$4)+(C7*8*Configuration!$C$4))*$Q$1 -> 6.24e-05 | E7: 0 | F7: =(D7+E7+$Q$3) -> 8.24e-05 | G7: Refon | H7: Isoact | I7: =VLOOKUP(G7,$M$19:$N$23,2,FALSE) + VLOOKUP(H7,$M$19:$N$24,2,FALSE) -> 0.00825 | K7: =SUM(B7:C7) -> 12 | L7: Read Cell Voltage Register Group B
A8: RDCVC | B8: 4 | C8: =8*Configuration!$C$2 -> 8 | D8: =((B8*8*Configuration!$C$4)+(C8*8*Configuration!$C$4))*$Q$1 -> 6.24e-05 | E8: 0 | F8: =(D8+E8+$Q$3) -> 8.24e-05 | G8: Refon | H8: Isoact | I8: =VLOOKUP(G8,$M$19:$N$23,2,FALSE) + VLOOKUP(H8,$M$19:$N$24,2,FALSE) -> 0.00825 | K8: =SUM(B8:C8) -> 12 | L8: Read Cell Voltage Register Group C
A9: RDCVD | B9: 4 | C9: =8*Configuration!$C$2 -> 8 | D9: =((B9*8*Configuration!$C$4)+(C9*8*Configuration!$C$4))*$Q$1 -> 6.24e-05 | E9: 0 | F9: =(D9+E9+$Q$3) -> 8.24e-05 | G9: Refon | H9: Isoact | I9: =VLOOKUP(G9,$M$19:$N$23,2,FALSE) + VLOOKUP(H9,$M$19:$N$24,2,FALSE) -> 0.00825 | K9: =SUM(B9:C9) -> 12 | L9: Read Cell Voltage Register Group D
A10: RDCVE | B10: 4 | C10: =8*Configuration!$C$2 -> 8 | D10: =((B10*8*Configuration!$C$4)+(C10*8*Configuration!$C$4))*$Q$1 -> 6.24e-05 | E10: 0 | F10: =(D10+E10+$Q$3) -> 8.24e-05 | G10: Refon | H10: Isoact | I10: =VLOOKUP(G10,$M$19:$N$23,2,FALSE) + VLOOKUP(H10,$M$19:$N$24,2,FALSE) -> 0.00825 | K10: =SUM(B10:C10) -> 12 | L10: Read Cell Voltage Register Group E
A11: RDCVF | B11: 4 | C11: =8*Configuration!$C$2 -> 8 | D11: =((B11*8*Configuration!$C$4)+(C11*8*Configuration!$C$4))*$Q$1 -> 6.24e-05 | E11: 0 | F11: =(D11+E11+$Q$3) -> 8.24e-05 | G11: Refon | H11: Isoact | I11: =VLOOKUP(G11,$M$19:$N$23,2,FALSE) + VLOOKUP(H11,$M$19:$N$24,2,FALSE) -> 0.00825 | K11: =SUM(B11:C11) -> 12 | L11: Read Cell Voltage Register Group F
A12: RDCVALL | B12: 4 | C12: =36*Configuration!$C$2+2 -> 38 | D12: =((B12*8*Configuration!$C$4)+(C12*8*Configuration!$C$4))*$Q$1 -> 0.0002184 | E12: 0 | F12: =(D12+E12+$Q$3) -> 0.0002384 | G12: Refon | H12: Isoact | I12: =VLOOKUP(G12,$M$19:$N$23,2,FALSE) + VLOOKUP(H12,$M$19:$N$24,2,FALSE) -> 0.00825 | K12: =SUM(B12:C12) -> 42 | L12: Read All Cell Results
A13: RDACA | B13: 4 | C13: =8*Configuration!$C$2 -> 8 | D13: =((B13*8*Configuration!$C$4)+(C13*8*Configuration!$C$4))*$Q$1 -> 6.24e-05 | E13: 0 | F13: =(D13+E13+$Q$3) -> 8.24e-05 | G13: Refon | H13: Isoact | I13: =VLOOKUP(G13,$M$19:$N$23,2,FALSE) + VLOOKUP(H13,$M$19:$N$24,2,FALSE) -> 0.00825 | K13: =SUM(B13:C13) -> 12 | L13: Read Averaged Cell Voltage Register Group A
A14: RDACB | B14: 4 | C14: =8*Configuration!$C$2 -> 8 | D14: =((B14*8*Configuration!$C$4)+(C14*8*Configuration!$C$4))*$Q$1 -> 6.24e-05 | E14: 0 | F14: =(D14+E14+$Q$3) -> 8.24e-05 | G14: Refon | H14: Isoact | I14: =VLOOKUP(G14,$M$19:$N$23,2,FALSE) + VLOOKUP(H14,$M$19:$N$24,2,FALSE) -> 0.00825 | K14: =SUM(B14:C14) -> 12 | L14: Read Averaged Cell Voltage Register Group B
A15: RDACC | B15: 4 | C15: =8*Configuration!$C$2 -> 8 | D15: =((B15*8*Configuration!$C$4)+(C15*8*Configuration!$C$4))*$Q$1 -> 6.24e-05 | E15: 0 | F15: =(D15+E15+$Q$3) -> 8.24e-05 | G15: Refon | H15: Isoact | I15: =VLOOKUP(G15,$M$19:$N$23,2,FALSE) + VLOOKUP(H15,$M$19:$N$24,2,FALSE) -> 0.00825 | K15: =SUM(B15:C15) -> 12 | L15: Read Averaged Cell Voltage Register Group C
A16: RDACD | B16: 4 | C16: =8*Configuration!$C$2 -> 8 | D16: =((B16*8*Configuration!$C$4)+(C16*8*Configuration!$C$4))*$Q$1 -> 6.24e-05 | E16: 0 | F16: =(D16+E16+$Q$3) -> 8.24e-05 | G16: Refon | H16: Isoact | I16: =VLOOKUP(G16,$M$19:$N$23,2,FALSE) + VLOOKUP(H16,$M$19:$N$24,2,FALSE) -> 0.00825 | K16: =SUM(B16:C16) -> 12 | L16: Read Averaged Cell Voltage Register Group D
A17: RDACE | B17: 4 | C17: =8*Configuration!$C$2 -> 8 | D17: =((B17*8*Configuration!$C$4)+(C17*8*Configuration!$C$4))*$Q$1 -> 6.24e-05 | E17: 0 | F17: =(D17+E17+$Q$3) -> 8.24e-05 | G17: Refon | H17: Isoact | I17: =VLOOKUP(G17,$M$19:$N$23,2,FALSE) + VLOOKUP(H17,$M$19:$N$24,2,FALSE) -> 0.00825 | K17: =SUM(B17:C17) -> 12 | L17: Read Averaged Cell Voltage Register Group E
A18: RDACF | B18: 4 | C18: =8*Configuration!$C$2 -> 8 | D18: =((B18*8*Configuration!$C$4)+(C18*8*Configuration!$C$4))*$Q$1 -> 6.24e-05 | E18: 0 | F18: =(D18+E18+$Q$3) -> 8.24e-05 | G18: Refon | H18: Isoact | I18: =VLOOKUP(G18,$M$19:$N$23,2,FALSE) + VLOOKUP(H18,$M$19:$N$24,2,FALSE) -> 0.00825 | K18: =SUM(B18:C18) -> 12 | L18: Read Averaged Cell Voltage Register Group F | M18: State Currents | P18: 7khz | Q18: ADC Mode
A19: RDACALL | B19: 4 | C19: =36*Configuration!$C$2+2 -> 38 | D19: =((B19*8*Configuration!$C$4)+(C19*8*Configuration!$C$4))*$Q$1 -> 0.0002184 | E19: 0 | F19: =(D19+E19+$Q$3) -> 0.0002384 | G19: Refon | H19: Isoact | I19: =VLOOKUP(G19,$M$19:$N$23,2,FALSE) + VLOOKUP(H19,$M$19:$N$24,2,FALSE) -> 0.00825 | K19: =SUM(B19:C19) -> 42 | L19: Read All Avg Cell Results | M19: Sleep | N19: 5.85e-06 | P19: 0 | Q19: mcal value
A20: RDSVA | B20: 4 | C20: =8*Configuration!$C$2 -> 8 | D20: =((B20*8*Configuration!$C$4)+(C20*8*Configuration!$C$4))*$Q$1 -> 6.24e-05 | E20: 0 | F20: =(D20+E20+$Q$3) -> 8.24e-05 | G20: Refon | H20: Isoact | I20: =VLOOKUP(G20,$M$19:$N$23,2,FALSE) + VLOOKUP(H20,$M$19:$N$24,2,FALSE) -> 0.00825 | K20: =SUM(B20:C20) -> 12 | L20: Read S Voltage Register Group A | M20: Standby | N20: 6e-05 | P20: 0 | Q20: OWRNG value
A21: RDSVB | B21: 4 | C21: =8*Configuration!$C$2 -> 8 | D21: =((B21*8*Configuration!$C$4)+(C21*8*Configuration!$C$4))*$Q$1 -> 6.24e-05 | E21: 0 | F21: =(D21+E21+$Q$3) -> 8.24e-05 | G21: Refon | H21: Isoact | I21: =VLOOKUP(G21,$M$19:$N$23,2,FALSE) + VLOOKUP(H21,$M$19:$N$24,2,FALSE) -> 0.00825 | K21: =SUM(B21:C21) -> 12 | L21: Read S Voltage Register Group B | M21: Refon | N21: 0.00125 | P21: 4 | Q21: OWC value
A22: RDSVC | B22: 4 | C22: =8*Configuration!$C$2 -> 8 | D22: =((B22*8*Configuration!$C$4)+(C22*8*Configuration!$C$4))*$Q$1 -> 6.24e-05 | E22: 0 | F22: =(D22+E22+$Q$3) -> 8.24e-05 | G22: Refon | H22: Isoact | I22: =VLOOKUP(G22,$M$19:$N$23,2,FALSE) + VLOOKUP(H22,$M$19:$N$24,2,FALSE) -> 0.00825 | K22: =SUM(B22:C22) -> 12 | L22: Read S Voltage Register Group C | M22: Meas | N22: 0.0112 | P22: 3 | Q22: OWA value
A23: RDSVD | B23: 4 | C23: =8*Configuration!$C$2 -> 8 | D23: =((B23*8*Configuration!$C$4)+(C23*8*Configuration!$C$4))*$Q$1 -> 6.24e-05 | E23: 0 | F23: =(D23+E23+$Q$3) -> 8.24e-05 | G23: Refon | H23: Isoact | I23: =VLOOKUP(G23,$M$19:$N$23,2,FALSE) + VLOOKUP(H23,$M$19:$N$24,2,FALSE) -> 0.00825 | K23: =SUM(B23:C23) -> 12 | L23: Read S Voltage Register Group D | M23: Isordy | N23: 0.004 | P23: 0 | Q23: SOAKON
A24: RDSVE | B24: 4 | C24: =8*Configuration!$C$2 -> 8 | D24: =((B24*8*Configuration!$C$4)+(C24*8*Configuration!$C$4))*$Q$1 -> 6.24e-05 | E24: 0 | F24: =(D24+E24+$Q$3) -> 8.24e-05 | G24: Refon | H24: Isoact | I24: =VLOOKUP(G24,$M$19:$N$23,2,FALSE) + VLOOKUP(H24,$M$19:$N$24,2,FALSE) -> 0.00825 | K24: =SUM(B24:C24) -> 12 | L24: Read S Voltage Register Group E | M24: Isoact | N24: 0.007 | V24: Conversion times for ADOW command measuring | AD24: (ADOW, CVOW and AXOW ALWAYS USES tSOAK)
A25: RDSVF | B25: 4 | C25: =8*Configuration!$C$2 -> 8 | D25: =((B25*8*Configuration!$C$4)+(C25*8*Configuration!$C$4))*$Q$1 -> 6.24e-05 | E25: 0 | F25: =(D25+E25+$Q$3) -> 8.24e-05 | G25: Refon | H25: Isoact | I25: =VLOOKUP(G25,$M$19:$N$23,2,FALSE) + VLOOKUP(H25,$M$19:$N$24,2,FALSE) -> 0.00825 | K25: =SUM(B25:C25) -> 12 | L25: Read S Voltage Register Group F | W25: CONVERSION TIMES (in ms) | AE25: The CVOW command operates on all cells. There is no option to operate on only 2 cells.
A26: RDSALL | B26: 4 | C26: =36*Configuration!$C$2+2 -> 38 | D26: =((B26*8*Configuration!$C$4)+(C26*8*Configuration!$C$4))*$Q$1 -> 0.0002184 | E26: 0 | F26: =(D26+E26+$Q$3) -> 0.0002384 | G26: Refon | H26: Isoact | I26: =VLOOKUP(G26,$M$19:$N$23,2,FALSE) + VLOOKUP(H26,$M$19:$N$24,2,FALSE) -> 0.00825 | K26: =SUM(B26:C26) -> 42 | L26: Read All S Results | V26: MODE | W26: t1M | X26: t2M | Y26: t5M | Z26: t6M | AA26: tC,MCAL=0 | AB26: tC,MCAL=1
A27: RDCSALL | B27: 4 | C27: =72*Configuration!$C$2+2 -> 74 | D27: =((B27*8*Configuration!$C$4)+(C27*8*Configuration!$C$4))*$Q$1 -> 0.0004056 | E27: 0 | F27: =(D27+E27+$Q$3) -> 0.0004256 | G27: Refon | H27: Isoact | I27: =VLOOKUP(G27,$M$19:$N$23,2,FALSE) + VLOOKUP(H27,$M$19:$N$24,2,FALSE) -> 0.00825 | K27: =SUM(B27:C27) -> 78 | L27: Read all C & S Results | V27: 27kHz | W27: 63 | X27: 111 | Y27: 256 | Z27: 304 | AA27: 576 | AB27: 1158 | AC27: =AA27-Z27 -> 272 | AD27: =48*6+14 -> 302 | AE27: =AC27+AD27 -> 574
A28: RDACSALL | B28: 4 | C28: =72*Configuration!$C$2+2 -> 74 | D28: =((B28*8*Configuration!$C$4)+(C28*8*Configuration!$C$4))*$Q$1 -> 0.0004056 | E28: 0 | F28: =(D28+E28+$Q$3) -> 0.0004256 | G28: Refon | H28: Isoact | I28: =VLOOKUP(G28,$M$19:$N$23,2,FALSE) + VLOOKUP(H28,$M$19:$N$24,2,FALSE) -> 0.00825 | K28: =SUM(B28:C28) -> 78 | L28: Read all Avg C & S Results | V28: 14kHz | W28: 92 | X28: 170 | Y28: 401 | Z28: 479 | AA28: 750 | AB28: 1332 | AC28: =AA28-Z28 -> 271
A29: RDFCA | B29: 4 | C29: =8*Configuration!$C$2 -> 8 | D29: =((B29*8*Configuration!$C$4)+(C29*8*Configuration!$C$4))*$Q$1 -> 6.24e-05 | E29: 0 | F29: =(D29+E29+$Q$3) -> 8.24e-05 | G29: Refon | H29: Isoact | I29: =VLOOKUP(G29,$M$19:$N$23,2,FALSE) + VLOOKUP(H29,$M$19:$N$24,2,FALSE) -> 0.00825 | K29: =SUM(B29:C29) -> 12 | L29: Read Filt. Cell Voltage Register Group A | V29: 7kHz | W29: 150 | X29: 286 | Y29: 692 | Z29: 828 | AA29: 1216 | AB29: 2380 | AC29: =AA29-Z29 -> 388
A30: RDFCB | B30: 4 | C30: =8*Configuration!$C$2 -> 8 | D30: =((B30*8*Configuration!$C$4)+(C30*8*Configuration!$C$4))*$Q$1 -> 6.24e-05 | E30: 0 | F30: =(D30+E30+$Q$3) -> 8.24e-05 | G30: Refon | H30: Isoact | I30: =VLOOKUP(G30,$M$19:$N$23,2,FALSE) + VLOOKUP(H30,$M$19:$N$24,2,FALSE) -> 0.00825 | K30: =SUM(B30:C30) -> 12 | L30: Read Filt. Cell Voltage Register Group B | V30: 3kHz | W30: 267 | X30: 519 | Y30: 1274 | Z30: 1526 | AA30: 1914 | AB30: 3078 | AC30: =AA30-Z30 -> 388
A31: RDFCC | B31: 4 | C31: =8*Configuration!$C$2 -> 8 | D31: =((B31*8*Configuration!$C$4)+(C31*8*Configuration!$C$4))*$Q$1 -> 6.24e-05 | E31: 0 | F31: =(D31+E31+$Q$3) -> 8.24e-05 | G31: Refon | H31: Isoact | I31: =VLOOKUP(G31,$M$19:$N$23,2,FALSE) + VLOOKUP(H31,$M$19:$N$24,2,FALSE) -> 0.00825 | K31: =SUM(B31:C31) -> 12 | L31: Read Filt. Cell Voltage Register Group C | Q31: =(2^((5+(6*P20)+(P21)))/(3.3*10^6)) -> 0.00015515152 | R31: (CV cmds Soak Time) | V31: 2kHz | W31: 500 | X31: 984 | Y31: 2438 | Z31: 2922 | AA31: 3310 | AB31: 4474 | AC31: =AA31-Z31 -> 388
A32: RDFCD | B32: 4 | C32: =8*Configuration!$C$2 -> 8 | D32: =((B32*8*Configuration!$C$4)+(C32*8*Configuration!$C$4))*$Q$1 -> 6.24e-05 | E32: 0 | F32: =(D32+E32+$Q$3) -> 8.24e-05 | G32: Refon | H32: Isoact | I32: =VLOOKUP(G32,$M$19:$N$23,2,FALSE) + VLOOKUP(H32,$M$19:$N$24,2,FALSE) -> 0.00825 | K32: =SUM(B32:C32) -> 12 | L32: Read Filt. Cell Voltage Register Group D | O32: ADOW Conv time | Q32: =VLOOKUP(P18,$V$27:$AB$34,6,FALSE)*10^-6 -> 0.001216 | R32: =VLOOKUP(P18,$V$27:$AB$34,7,FALSE)*10^-6 -> 0.00238 | V32: 1kHz | W32: 965 | X32: 1915 | Y32: 4765 | Z32: 5715 | AA32: 6103 | AB32: 7267 | AC32: =AA32-Z32 -> 388
A33: RDFCE | B33: 4 | C33: =8*Configuration!$C$2 -> 8 | D33: =((B33*8*Configuration!$C$4)+(C33*8*Configuration!$C$4))*$Q$1 -> 6.24e-05 | E33: 0 | F33: =(D33+E33+$Q$3) -> 8.24e-05 | G33: Refon | H33: Isoact | I33: =VLOOKUP(G33,$M$19:$N$23,2,FALSE) + VLOOKUP(H33,$M$19:$N$24,2,FALSE) -> 0.00825 | K33: =SUM(B33:C33) -> 12 | L33: Read Filt. Cell Voltage Register Group E | N33: 12 Cells | O33: Conversion Time ADOW | P33: =INDEX(Q32:R32,1,P19+1)+6*Q31 -> 0.0021469091 | V33: 422Hz | W33: 1896 | X33: 3777 | Y33: 9420 | Z33: 11301 | AA33: 11689 | AB33: 12853 | AC33: =AA33-Z33 -> 388
A34: RDFCF | B34: 4 | C34: =8*Configuration!$C$2 -> 8 | D34: =((B34*8*Configuration!$C$4)+(C34*8*Configuration!$C$4))*$Q$1 -> 6.24e-05 | E34: 0 | F34: =(D34+E34+$Q$3) -> 8.24e-05 | G34: Refon | H34: Isoact | I34: =VLOOKUP(G34,$M$19:$N$23,2,FALSE) + VLOOKUP(H34,$M$19:$N$24,2,FALSE) -> 0.00825 | K34: =SUM(B34:C34) -> 12 | L34: Read Filt. Cell Voltage Register Group F | V34: 26Hz | W34: 29823 | X34: 59632 | Y34: 149056 | Z34: 178864 | AA34: 182743 | AB34: 201362 | AC34: =AA34-Z34 -> 3879
A35: RDFCALL | B35: 4 | C35: =36*Configuration!$C$2+2 -> 38 | D35: =((B35*8*Configuration!$C$4)+(C35*8*Configuration!$C$4))*$Q$1 -> 0.0002184 | E35: 0 | F35: =(D35+E35+$Q$3) -> 0.0002384 | G35: Refon | H35: Isoact | I35: =VLOOKUP(G35,$M$19:$N$23,2,FALSE) + VLOOKUP(H35,$M$19:$N$24,2,FALSE) -> 0.00825 | K35: =SUM(B35:C35) -> 42 | L35: Read All Filt. Cell Results
A36: RDAUXA | B36: 4 | C36: =8*Configuration!$C$2 -> 8 | D36: =((B36*8*Configuration!$C$4)+(C36*8*Configuration!$C$4))*$Q$1 -> 6.24e-05 | E36: 0 | F36: =(D36+E36+$Q$3) -> 8.24e-05 | G36: Refon | H36: Isoact | I36: =VLOOKUP(G36,$M$19:$N$23,2,FALSE) + VLOOKUP(H36,$M$19:$N$24,2,FALSE) -> 0.00825 | K36: =SUM(B36:C36) -> 12 | L36: Read Auxiliary Register Group A | AG36: ADCV command measuring 2 cells
A37: RDAUXB | B37: 4 | C37: =8*Configuration!$C$2 -> 8 | D37: =((B37*8*Configuration!$C$4)+(C37*8*Configuration!$C$4))*$Q$1 -> 6.24e-05 | E37: 0 | F37: =(D37+E37+$Q$3) -> 8.24e-05 | G37: Refon | H37: Isoact | I37: =VLOOKUP(G37,$M$19:$N$23,2,FALSE) + VLOOKUP(H37,$M$19:$N$24,2,FALSE) -> 0.00825 | K37: =SUM(B37:C37) -> 12 | L37: Read Auxiliary Register Group B | N37: 12 Cells | O37: ADC Conv time | P37: =($P$23*$Q$31)*6+VLOOKUP(P18,$V$39:$AC$46,7+P19,FALSE)*10^-6 -> 0.001216 | W37: CONVERSION TIMES (ADCV 12 Cells) (in ms) | AG37: CONVERSION TIMES (in ms)
A38: RDAUXC | B38: 4 | C38: =8*Configuration!$C$2 -> 8 | D38: =((B38*8*Configuration!$C$4)+(C38*8*Configuration!$C$4))*$Q$1 -> 6.24e-05 | E38: 0 | F38: =(D38+E38+$Q$3) -> 8.24e-05 | G38: Refon | H38: Isoact | I38: =VLOOKUP(G38,$M$19:$N$23,2,FALSE) + VLOOKUP(H38,$M$19:$N$24,2,FALSE) -> 0.00825 | K38: =SUM(B38:C38) -> 12 | L38: Read Auxiliary Register Group C | N38: 2 Cells | O38: ADC Conv time | P38: =($P$23*$Q$31)*2+VLOOKUP(P18,AF38:AI46,4,FALSE)*10^-6 -> 0.000402 | V38: MODE | W38: t0 | X38: t1M | Y38: t2M | Z38: t5M | AA38: t6M | AB38: tC,MCAL=0 | AC38: tC,MCAL=1 | AF38: MODE | AG38: t0 | AH38: t1M | AI38: tC
A39: RDAUXD | B39: 4 | C39: =8*Configuration!$C$2 -> 8 | D39: =((B39*8*Configuration!$C$4)+(C39*8*Configuration!$C$4))*$Q$1 -> 6.24e-05 | E39: 0 | F39: =(D39+E39+$Q$3) -> 8.24e-05 | G39: Refon | H39: Isoact | I39: =VLOOKUP(G39,$M$19:$N$23,2,FALSE) + VLOOKUP(H39,$M$19:$N$24,2,FALSE) -> 0.00825 | K39: =SUM(B39:C39) -> 12 | L39: Read Auxiliary Register Group D | V39: 27kHz | W39: 0 | X39: 63 | Y39: 111 | Z39: 256 | AA39: 304 | AB39: 576 | AC39: 1158 | AD39: =AB39-AA39 -> 272 | AE39: =AC39-AA39 -> 854 | AF39: 27kHz | AG39: 0 | AH39: 63 | AI39: 199 | AJ39: =AI39-AH39 -> 136 | AL39: =AJ39+X39 -> 199 | AM39: =AE39/6 -> 142.33333 | AN39: =AL39+Y39 -> 310
A40: RDRAXA | B40: 4 | C40: =8*Configuration!$C$2 -> 8 | D40: =((B40*8*Configuration!$C$4)+(C40*8*Configuration!$C$4))*$Q$1 -> 6.24e-05 | E40: 0 | F40: =(D40+E40+$Q$3) -> 8.24e-05 | G40: Refon | H40: Isoact | I40: =VLOOKUP(G40,$M$19:$N$23,2,FALSE) + VLOOKUP(H40,$M$19:$N$24,2,FALSE) -> 0.00825 | K40: =SUM(B40:C40) -> 12 | L40: Read Redundant Auxiliary Register Group A | V40: 14kHz | W40: 0 | X40: 92 | Y40: 170 | Z40: 401 | AA40: 479 | AB40: 750 | AC40: 1332 | AD40: =AB40-AA40 -> 271 | AE40: =AC40-AA40 -> 853 | AF40: 14kHz | AG40: 0 | AH40: 93 | AI40: 228 | AJ40: =AI40-AH40 -> 135 | AL40: =AJ40+X40 -> 227 | AM40: =AE40/6 -> 142.16667 | AN40: =AL40+Y40 -> 397
...

Sheet SPF IDs
A1: Name of SM | B1: Number of SM | C1: Addr. Failure Mode
A2: SM_VCELL_RED | B2: SM1 | C2: SPF | D2: Covered
A3: SM_IIR_RED | B3: SM2 | C3: SPF | D3: Not Covered Yet
A4: SM_SPI_RED | B4: SM3 | C4: SPF | D4: Unknown
A5: SM_SPI_PEC | B5: SM4 | C5: SPF
A6: SM_CLOCK_MON | B6: SM5 | C6: SPF
A7: SM_FREEZE_SEQ | B7: SM6 | C7: SPF
A8: SM_POWER_MON | B8: SM7 | C8: SPF
A9: SM_POWER_OOR | B9: SM8 | C9: SPF
A10: SM_CELL_OWD | B10: SM9 | C10: SPF (application)
A11: SM_VCELL_OOR | B11: SM12 | C11: SPF
A12: SM_VGPIO_RED | B12: SM14 | C12: SPF
A13: SM_VGPIO_OOR | B13: SM15 | C13: SPF
A14: SM_SPI_CNT | B14: SM16 | C14: SPF
A15: SM_TMOD_IND | B15: SM17 | C15: SPF
A16: SM_DIETEMP_OOR | B16: SM18 | C16: SPF
... A29: SM_NVM_ECC_DIAG | B29: SM31 | C29: LF
